<?xml version="1.0" encoding="utf-8"?>
<!-- =================================================================================== -->
<!-- |    This document was autogenerated by xacro from sgr532.urdf.xacro              | -->
<!-- |    EDITING THIS FILE BY HAND IS NOT RECOMMENDED                                 | -->
<!-- =================================================================================== -->
<robot name="sgr532">
  <link name="sgr532/base_link">
    <inertial>
      <origin rpy="0 0 0" xyz="0.00793179544277737 2.48115460577673E-19 0.0312047945759253"/>
      <mass value="0.940146705073746"/>
      <inertia ixx="0.000950195835062344" ixy="3.14825974312405E-20" ixz="-0.000200082473207336" iyy="0.00267650790326047" iyz="-1.01412991222915E-19" izz="0.002902663900239"/>
    </inertial>
    <visual>
      <origin rpy="0 0 0" xyz="0 0 0"/>
      <geometry>
        <mesh filename="package://sagittarius_descriptions/meshes/sagittarius_base_link.STL"/>
      </geometry>
      <material name="">
        <color rgba="1 1 1 1"/>
      </material>
    </visual>
    <collision>
      <origin rpy="0 0 0" xyz="0 0 0"/>
      <geometry>
        <mesh filename="package://sagittarius_descriptions/meshes/sagittarius_base_link.STL"/>
      </geometry>
    </collision>
  </link>
  <link name="sgr532/link1">
    <inertial>
      <origin rpy="0 0 0" xyz="-7.74579608786574E-10 3.23354786979222E-12 0.0344870497564283"/>
      <mass value="0.123745079127031"/>
      <inertia ixx="8.15779591743416E-05" ixy="-4.25325094802094E-15" ixz="-2.22201794150093E-12" iyy="6.7607001964135E-05" iyz="-1.59127137655435E-14" izz="4.41297902395382E-05"/>
    </inertial>
    <visual>
      <origin rpy="0 0 0" xyz="0 0 0"/>
      <geometry>
        <mesh filename="package://sagittarius_descriptions/meshes/link1.STL"/>
      </geometry>
      <material name="">
        <color rgba="1 1 1 1"/>
      </material>
    </visual>
    <collision>
      <origin rpy="0 0 0" xyz="0 0 0"/>
      <geometry>
        <mesh filename="package://sagittarius_descriptions/meshes/link1.STL"/>
      </geometry>
    </collision>
  </link>
  <joint name="joint1" type="revolute">
    <origin rpy="0 0 0" xyz="0.045 0 0.07"/>
    <parent link="sgr532/base_link"/>
    <child link="sgr532/link1"/>
    <axis xyz="0 0 -1"/>
    <limit effort="100" lower="-2" upper="2" velocity="3.14"/>
  </joint>
  <transmission name="trans_joint1">
    <type>transmission_interface/SimpleTransmission</type>
    <joint name="joint1">
      <hardwareInterface>hardware_interface/EffortJointInterface</hardwareInterface>
    </joint>
    <actuator name="joint1_motor">
      <mechanicalReduction>1</mechanicalReduction>
    </actuator>
  </transmission>
  <link name="sgr532/link2">
    <inertial>
      <origin rpy="0 0 0" xyz="0.0119015312584793 -1.03639845764692E-08 0.150755903867182"/>
      <mass value="0.156160822791157"/>
      <inertia ixx="0.000429266751802994" ixy="-2.27426165787001E-11" ixz="-5.58862834004722E-05" iyy="0.000444676097748043" iyz="-2.41993274420629E-10" izz="7.916162292894E-05"/>
    </inertial>
    <visual>
      <origin rpy="0 0 0" xyz="0 0 0"/>
      <geometry>
        <mesh filename="package://sagittarius_descriptions/meshes/link2.STL"/>
      </geometry>
      <material name="">
        <color rgba="0.752941176470588 0.752941176470588 0.752941176470588 1"/>
      </material>
    </visual>
    <collision>
      <origin rpy="0 0 0" xyz="0 0 0"/>
      <geometry>
        <mesh filename="package://sagittarius_descriptions/meshes/link2.STL"/>
      </geometry>
    </collision>
  </link>
  <joint name="joint2" type="revolute">
    <origin rpy="0 0 0" xyz="0 -0.0001 0.055"/>
    <parent link="sgr532/link1"/>
    <child link="sgr532/link2"/>
    <axis xyz="0 -1 0"/>
    <limit effort="100" lower="-1.57" upper="1.4" velocity="3.14"/>
  </joint>
  <transmission name="trans_joint2">
    <type>transmission_interface/SimpleTransmission</type>
    <joint name="joint2">
      <hardwareInterface>hardware_interface/EffortJointInterface</hardwareInterface>
    </joint>
    <actuator name="joint2_motor">
      <mechanicalReduction>1</mechanicalReduction>
    </actuator>
  </transmission>
  <link name="sgr532/link3">
    <inertial>
      <origin rpy="0 0 0" xyz="0.054357321065004 -2.67256405253992E-08 0.00064594073830132"/>
      <mass value="0.0366487313200473"/>
      <inertia ixx="9.28701176876329E-06" ixy="-2.23878504272996E-11" ixz="6.34310578103811E-07" iyy="2.0727596617309E-05" iyz="-1.71647322080315E-11" izz="2.42416271089979E-05"/>
    </inertial>
    <visual>
      <origin rpy="0 0 0" xyz="0 0 0"/>
      <geometry>
        <mesh filename="package://sagittarius_descriptions/meshes/link3.STL"/>
      </geometry>
      <material name="">
        <color rgba="0.752941176470588 0.752941176470588 0.752941176470588 1"/>
      </material>
    </visual>
    <collision>
      <origin rpy="0 0 0" xyz="0 0 0"/>
      <geometry>
        <mesh filename="package://sagittarius_descriptions/meshes/link3.STL"/>
      </geometry>
    </collision>
  </link>
  <joint name="joint3" type="revolute">
    <origin rpy="0 0 0" xyz="0.033 -0.0001 0.179"/>
    <parent link="sgr532/link2"/>
    <child link="sgr532/link3"/>
    <axis xyz="0 -1 0"/>
    <limit effort="100" lower="-1.48" upper="1.8" velocity="3.14"/>
  </joint>
  <transmission name="trans_joint3">
    <type>transmission_interface/SimpleTransmission</type>
    <joint name="joint3">
      <hardwareInterface>hardware_interface/EffortJointInterface</hardwareInterface>
    </joint>
    <actuator name="joint3_motor">
      <mechanicalReduction>1</mechanicalReduction>
    </actuator>
  </transmission>
  <link name="sgr532/link4">
    <inertial>
      <origin rpy="0 0 0" xyz="0.0444029485674779 -0.00527865310158246 -1.43738021485262E-10"/>
      <mass value="0.124950088011432"/>
      <inertia ixx="3.52699895078887E-05" ixy="-1.14870103744551E-05" ixz="2.45948329713632E-14" iyy="0.00010928557067047" iyz="-3.42525315676607E-12" izz="0.000121451732690361"/>
    </inertial>
    <visual>
      <origin rpy="0 0 0" xyz="0 0 0"/>
      <geometry>
        <mesh filename="package://sagittarius_descriptions/meshes/link4.STL"/>
      </geometry>
      <material name="">
        <color rgba="0.752941176470588 0.752941176470588 0.752941176470588 1"/>
      </material>
    </visual>
    <collision>
      <origin rpy="0 0 0" xyz="0 0 0"/>
      <geometry>
        <mesh filename="package://sagittarius_descriptions/meshes/link4.STL"/>
      </geometry>
    </collision>
  </link>
  <joint name="joint4" type="revolute">
    <origin rpy="0 0 0" xyz="0.0845 0 0"/>
    <parent link="sgr532/link3"/>
    <child link="sgr532/link4"/>
    <axis xyz="-1 0 0"/>
    <limit effort="100" lower="-2.90" upper="2.90" velocity="3.14"/>
  </joint>
  <transmission name="trans_joint4">
    <type>transmission_interface/SimpleTransmission</type>
    <joint name="joint4">
      <hardwareInterface>hardware_interface/EffortJointInterface</hardwareInterface>
    </joint>
    <actuator name="joint4_motor">
      <mechanicalReduction>1</mechanicalReduction>
    </actuator>
  </transmission>
  <link name="sgr532/link5">
    <inertial>
      <origin rpy="0 0 0" xyz="0.0391172635125616 1.22102848665318E-15 0.011359922796391"/>
      <mass value="0.0564710099602834"/>
      <inertia ixx="1.77667699918498E-05" ixy="3.77572698012408E-19" ixz="-6.79618041712231E-07" iyy="1.89643063051294E-05" iyz="1.78381670331667E-19" izz="1.66130972969903E-05"/>
    </inertial>
    <visual>
      <origin rpy="0 0 0" xyz="0 0 0"/>
      <geometry>
        <mesh filename="package://sagittarius_descriptions/meshes/link5.STL"/>
      </geometry>
      <material name="">
        <color rgba="0.752941176470588 0.752941176470588 0.752941176470588 1"/>
      </material>
    </visual>
    <collision>
      <origin rpy="0 0 0" xyz="0 0 0"/>
      <geometry>
        <mesh filename="package://sagittarius_descriptions/meshes/link5.STL"/>
      </geometry>
    </collision>
  </link>
  <joint name="joint5" type="revolute">
    <origin rpy="0 0 0" xyz="0.08435 0.00065 0"/>
    <parent link="sgr532/link4"/>
    <child link="sgr532/link5"/>
    <axis xyz="0 -1 0"/>
    <limit effort="100" lower="-1.8" upper="1.60" velocity="3.14"/>
  </joint>
  <transmission name="trans_joint5">
    <type>transmission_interface/SimpleTransmission</type>
    <joint name="joint5">
      <hardwareInterface>hardware_interface/EffortJointInterface</hardwareInterface>
    </joint>
    <actuator name="joint5_motor">
      <mechanicalReduction>1</mechanicalReduction>
    </actuator>
  </transmission>
  <link name="sgr532/link6">
    <inertial>
      <origin rpy="0 0 0" xyz="0.0330748503556987 -1.47583477394259E-10 0.00874151659437283"/>
      <mass value="0.0790875358325134"/>
      <inertia ixx="4.00727396068743E-05" ixy="1.5026227935429E-13" ixz="6.77337873337555E-06" iyy="4.37063090227749E-05" iyz="-1.73263828329941E-13" izz="5.69755186998711E-05"/>
    </inertial>
    <visual>
      <origin rpy="0 0 0" xyz="0 0 0"/>
      <geometry>
        <mesh filename="package://sagittarius_descriptions/meshes/link6.STL"/>
      </geometry>
      <material name="">
        <color rgba="0.752941176470588 0.752941176470588 0.752941176470588 1"/>
      </material>
    </visual>
    <collision>
      <origin rpy="0 0 0" xyz="0 0 0"/>
      <geometry>
        <mesh filename="package://sagittarius_descriptions/meshes/link6.STL"/>
      </geometry>
    </collision>
  </link>
  <joint name="joint6" type="revolute">
    <origin rpy="0 0 0" xyz="0.061387 0 0"/>
    <parent link="sgr532/link5"/>
    <child link="sgr532/link6"/>
    <axis xyz="-1 0 0"/>
    <limit effort="100" lower="-3.1" upper="3.1" velocity="3.14"/>
  </joint>
  <transmission name="trans_joint6">
    <type>transmission_interface/SimpleTransmission</type>
    <joint name="joint6">
      <hardwareInterface>hardware_interface/EffortJointInterface</hardwareInterface>
    </joint>
    <actuator name="joint6_motor">
      <mechanicalReduction>1</mechanicalReduction>
    </actuator>
  </transmission>
  <link name="sgr532/ar_tag_link">
  </link>
  <joint name="joint_ar_tag_frame" type="fixed">
    <origin rpy="0 0 0" xyz="-0.018 0 0.036"/>
    <parent link="sgr532/link6"/>
    <child link="sgr532/ar_tag_link"/>
    <axis xyz="0 0 0"/>
    <limit effort="100" lower="0" upper="0" velocity="3.14"/>
  </joint>
  <link name="sgr532/link_grasping_frame">
    <inertial>
      <origin rpy="0 0 0" xyz="-0.29292863789122 -0.000855248417215765 -0.182862893125548"/>
      <mass value="1.55422651132493"/>
      <inertia ixx="0.0246807389934657" ixy="6.12977506319177E-05" ixz="-0.0174568851774044" iyy="0.0450160124726729" iyz="0.000114187269419605" izz="0.0218809326193524"/>
    </inertial>
  </link>
  <joint name="joint_grasping_frame" type="fixed">
    <origin rpy="0 0 0" xyz="0.0557 0 0"/>
    <parent link="sgr532/link6"/>
    <child link="sgr532/link_grasping_frame"/>
    <axis xyz="0 0 0"/>
    <limit effort="100" lower="0" upper="0" velocity="3.10"/>
  </joint>
  <link name="sgr532/link_gripper_left">
    <inertial>
      <origin rpy="0 0 0" xyz="0.0168448613850675 0.00562743947549268 -3.34157867051821E-05"/>
      <mass value="0.0185082696416839"/>
      <inertia ixx="1.65620668352765E-06" ixy="3.12039082733024E-07" ixz="-1.06123823321138E-09" iyy="7.56731403094351E-06" iyz="5.54920898904154E-11" izz="6.37610666327876E-06"/>
    </inertial>
    <visual>
      <origin rpy="0 0 0" xyz="0 0 0"/>
      <geometry>
        <mesh filename="package://sagittarius_descriptions/meshes/link_gripper_left.STL"/>
      </geometry>
      <material name="">
        <color rgba="0.752941176470588 0.752941176470588 0.752941176470588 1"/>
      </material>
    </visual>
    <collision>
      <origin rpy="0 0 0" xyz="0 0 0"/>
      <geometry>
        <mesh filename="package://sagittarius_descriptions/meshes/link_gripper_left.STL"/>
      </geometry>
    </collision>
  </link>
  <joint name="joint_gripper_left" type="prismatic">
    <origin rpy="0 0 0" xyz="0.0695 0.033 0"/>
    <parent link="sgr532/link6"/>
    <child link="sgr532/link_gripper_left"/>
    <axis xyz="0 1 0"/>
    <limit effort="10" lower="-0.034" upper="0" velocity="1.14"/>
  </joint>
  <transmission name="trans_joint_gripper_left">
    <type>transmission_interface/SimpleTransmission</type>
    <joint name="joint_gripper_left">
      <hardwareInterface>hardware_interface/EffortJointInterface</hardwareInterface>
    </joint>
    <actuator name="joint_gripper_left_motor">
      <mechanicalReduction>1</mechanicalReduction>
    </actuator>
  </transmission>
  <link name="sgr532/link_gripper_right">
    <inertial>
      <origin rpy="0 0 0" xyz="0.0168448612901284 -0.00562743946967042 3.34158424380449E-05"/>
      <mass value="0.0185082695670405"/>
      <inertia ixx="1.65620670013429E-06" ixy="-3.12039085367371E-07" ixz="1.06121397059487E-09" iyy="7.56731399585561E-06" iyz="5.54960746810554E-11" izz="6.37610660879392E-06"/>
    </inertial>
    <visual>
      <origin rpy="0 0 0" xyz="0 0 0"/>
      <geometry>
        <mesh filename="package://sagittarius_descriptions/meshes/link_gripper_right.STL"/>
      </geometry>
      <material name="">
        <color rgba="0.752941176470588 0.752941176470588 0.752941176470588 1"/>
      </material>
    </visual>
    <collision>
      <origin rpy="0 0 0" xyz="0 0 0"/>
      <geometry>
        <mesh filename="package://sagittarius_descriptions/meshes/link_gripper_right.STL"/>
      </geometry>
    </collision>
  </link>
  <joint name="joint_gripper_right" type="prismatic">
    <origin rpy="0 0 0" xyz="0.0695 -0.033 0"/>
    <parent link="sgr532/link6"/>
    <child link="sgr532/link_gripper_right"/>
    <axis xyz="0 -1 0"/>
    <limit effort="10" lower="-0.034" upper="0" velocity="1.10"/>
  </joint>
  <transmission name="trans_joint_gripper_right">
    <type>transmission_interface/SimpleTransmission</type>
    <joint name="joint_gripper_right">
      <hardwareInterface>hardware_interface/EffortJointInterface</hardwareInterface>
    </joint>
    <actuator name="joint_gripper_right_motor">
      <mechanicalReduction>1</mechanicalReduction>
    </actuator>
  </transmission>
  <link name="sgr532/usb_cam_link"/>
  <joint name="joint_usb_cam_frame" type="fixed">
    <origin rpy="-1.57 0 -1.57" xyz="0.05 0 0.05825"/>
    <parent link="sgr532/link6"/>
    <child link="sgr532/usb_cam_link"/>
    <axis xyz="0 0 0"/>
    <limit effort="0" lower="0" upper="0" velocity="0"/>
  </joint>
</robot>
